Workbook
Name LandPrice: Inputs!$B$5
Name LandClosing: Inputs!$B$6
Name LandLtv: Inputs!$B$8
Name LandRate: Inputs!$B$9
Name LandPointsPct: Inputs!$B$10
Name TaxRate: Inputs!$B$11
Name HoaMonthly: Inputs!$B$12
Name PreConMonths: Inputs!$B$15
Name BuildMonths: Inputs!$B$16
Name ListEarlyMonths: Inputs!$B$17
Name ClosingDays: Inputs!$B$18
Name MonthDays: Inputs!$B$19
Name Ltc: Inputs!$B$22
Name LoanRate: Inputs!$B$23
Name PointsPct: Inputs!$B$24
Name DrawFee: Inputs!$B$25
Name TermMonths: Inputs!$B$26
Name ExtensionPct: Inputs!$B$27
Name ExtensionMonths: Inputs!$B$28
Name InterestMode: Inputs!$B$29
Name InsuranceRate: Inputs!$B$32
Name UtilBuild: Inputs!$B$33
Name UtilAfter: Inputs!$B$34
Name StagingMonthly: Inputs!$B$35
Name UpkeepMonthly: Inputs!$B$36
Name ListingPct: Inputs!$B$39
Name BuyerPct: Inputs!$B$40
Name ClosingPct: Inputs!$B$41
Name Concessions: Inputs!$B$42
Name BidSubtotal: Inputs!$G$32
Name ContingencyPct: Inputs!$G$33
Name Contingency: Inputs!$G$34
Name EstimateTotal: Inputs!$G$35
Name SoftCost: Inputs!$G$36
Name HardCost: Inputs!$G$37
Name colK: 'base'!$A$65:$A$79
Name colOvBuildClose: 'base'!$B$65:$B$79
Name colOvAll: 'base'!$C$65:$C$79
Name colOvBuild: 'base'!$D$65:$D$79
Name colOvAfter: 'base'!$E$65:$E$79
Name colOvListed: 'base'!$F$65:$F$79
Name colSine: 'base'!$G$65:$G$79
Name colDraw: 'base'!$H$65:$H$79
Name colSpend: 'base'!$I$65:$I$79
Name colSpendBefore: 'base'!$J$65:$J$79
Name colDrawnBefore: 'base'!$K$65:$K$79
Name colEqFirst: 'base'!$L$65:$L$79
Name colLoanDraw: 'base'!$M$65:$M$79
Name colEquitySpend: 'base'!$N$65:$N$79
Name colSpendThrough: 'base'!$O$65:$O$79
Name colDrawnThrough: 'base'!$P$65:$P$79
Name colBalanceStart: 'base'!$Q$65:$Q$79
Name colPoints: 'base'!$R$65:$R$79
Name colDrawFee: 'base'!$S$65:$S$79
Name colInterest: 'base'!$T$65:$T$79
Name colInterestPaid: 'base'!$U$65:$U$79
Name colInterestCap: 'base'!$V$65:$V$79
Name colBalanceEnd: 'base'!$W$65:$W$79
Name colLandInterest: 'base'!$X$65:$X$79
Name colExtensionFee: 'base'!$Y$65:$Y$79

Sheet Inputs
A1: Golden deal - inputs
A2: Money in dollars, rates as decimals. Source: src/engine/__fixtures__/golden-deal.inputs.json
A4: Lot | E4: Estimate (bids)
A5: Land price | B5: 295000 | E5: Code | F5: Division | G5: Amount
A6: Land closing costs | B6: 4000 | E6: plans | F6: soft | G6: 8500
A7: Land financing | B7: cash | E7: permits | F7: soft | G7: 26800
A8: Land loan LTV | B8: 0 | C8: 0 when bought for cash | E8: surveySoils | F8: soft | G8: 3200
A9: Land loan rate (annual) | B9: 0 | E9: excavation | F9: hard | G9: 22000
A10: Land loan points | B10: 0 | E10: utilities | F10: hard | G10: 15500
A11: Property tax rate (annual) | B11: 0.0048 | E11: foundation | F11: hard | G11: 62000
A12: HOA per month | B12: 0 | E12: framing | F12: hard | G12: 108000
E13: roofing | F13: hard | G13: 24000
A14: Timeline (months from land close) | E14: windows | F14: hard | G14: 31000
A15: Pre-construction months (P) | B15: 2 | E15: cladding | F15: hard | G15: 38000
A16: Build months (B) | B16: 9 | E16: insulation | F16: hard | G16: 10500
A17: List early months (L) | B17: 0 | E17: plumbing | F17: hard | G17: 33000
A18: Closing days after contract | B18: 35 | E18: electrical | F18: hard | G18: 29700
A19: Days per month | B19: =365/12 | E19: hvac | F19: hard | G19: 26500
E20: drywall | F20: hard | G20: 30000
A21: Construction loan | E21: trim | F21: hard | G21: 24500
A22: Loan-to-cost | B22: 0.8 | E22: cabinets | F22: hard | G22: 54000
A23: Rate (annual) | B23: 0.09 | E23: flooring | F23: hard | G23: 31000
A24: Points | B24: 0.01 | E24: paint | F24: hard | G24: 18000
A25: Draw fee per draw | B25: 200 | E25: fixtures | F25: hard | G25: 24000
A26: Term months (from build start) | B26: 12 | E26: garageDoors | F26: hard | G26: 6800
A27: Extension fee | B27: 0.005 | C27: of the commitment, per extension | E27: flatwork | F27: hard | G27: 16500
A28: Extension months | B28: 3 | E28: landscaping | F28: hard | G28: 20000
A29: Interest mode | B29: paid | C29: paid | capitalized | E29: cleaning | F29: hard | G29: 4150
E30: supervision | F30: hard | G30: 33300
A31: Carry
A32: Builder's risk insurance (annual, of estimate) | B32: 0.0035 | E32: Bid subtotal | G32: =SUM(G6:G30)
A33: Utilities per month, during build | B33: 150 | E33: Contingency rate | G33: 0.05
A34: Utilities per month, after completion | B34: 250 | E34: Contingency | G34: =ROUND(BidSubtotal*ContingencyPct,2)
A35: Staging per month, while listed | B35: 500 | E35: Estimate total | G35: =BidSubtotal+Contingency
A36: Upkeep per month, after completion | B36: 100 | E36: Soft costs (division soft) | G36: =SUMIF(F6:F30,"soft",G6:G30)
E37: Hard costs (incl. contingency) | G37: =EstimateTotal-SoftCost
A38: Selling
A39: Listing commission | B39: 0.025
A40: Buyer-agent commission | B40: 0.025
A41: Closing and title | B41: 0.01
...

Sheet base
A1: Golden deal - base scenario
A2: Every value below is a formula implementing the Reference cash-flow algorithm (dollars).
A4: Scenario inputs
A5: Sale price | B5: =Inputs!$B$46
A6: Days on market | B6: =Inputs!$C$46
A7: Cost overrun | B7: =Inputs!$D$46
A9: Times (months) - Reference step 1
A10: Build start = P | B10: =PreConMonths
A11: Completion = P + B | B11: =BuildStart+BuildMonths
A12: List = completion - L | B12: =Completion-ListEarlyMonths
A13: Contract = list + DOM / MONTH_DAYS | B13: =ListMonth+DomDays/MonthDays
A14: Sale close = max(contract + closingDays / MONTH_DAYS, completion) | B14: =MAX(Contract+ClosingDays/MonthDays,Completion)
A15: Loan maturity = build start + term | B15: =BuildStart+TermMonths
A16: Periods N = ceil(sale close) | B16: =CEILING(SaleClose,1)
A17: Period rows in this sheet | B17: =COUNT(colK)
A19: Costs and loan - Reference steps 2-8
A20: Soft actual = round(soft x (1 + overrun)) | B20: =ROUND(SoftCost*(1+Overrun),2)
A21: Hard actual = round(hard x (1 + overrun)) | B21: =ROUND(HardCost*(1+Overrun),2)
A22: Sum of draw sines | B22: =SUM(colSine)
A23: Loan commitment = round(LTC x estimate total) | B23: =ROUND(Ltc*EstimateTotal,2)
A24: Equity requirement = estimate total - commitment | B24: =EstimateTotal-Commitment
A25: Construction points = round(points x commitment) | B25: =IF(Commitment>0,ROUND(PointsPct*Commitment,2),0)
A26: Land loan = round(LTV x land price) | B26: =ROUND(LandLtv*LandPrice,2)
A27: Land points = round(points x land loan) | B27: =ROUND(LandPointsPct*LandLoan,2)
A28: Extensions n | B28: =IF(AND(Commitment>0,SaleClose>Maturity),CEILING((SaleClose-Maturity)/ExtensionMonths,1),0)
A29: Extension fee each = round(extension % x commitment) | B29: =ROUND(ExtensionPct*Commitment,2)
A30: Interest capitalized (1 = yes) | B30: =IF(InterestMode="capitalized",1,0)
A32: Sale (at sale close, booked on period N-1) - Reference step 11
A33: Commissions = round(price x (listing + buyer)) | B33: =ROUND(SalePrice*(ListingPct+BuyerPct),2)
A34: Closing = round(price x closing %) | B34: =ROUND(SalePrice*ClosingPct,2)
A35: Concessions | B35: =Concessions
A36: Net = price - commissions - closing - concessions | B36: =SalePrice-Commissions-SaleClosing-SaleConcessions
A37: Loan drawn | B37: =SUM(colLoanDraw)
A38: Capitalized interest | B38: =SUM(colInterestCap)
A39: Loan payoff = drawn + capitalized interest + land loan | B39: =LoanDrawn+CapInterest+LandLoan
A40: Equity return = net - payoff | B40: =NetProceeds-Payoff
A42: Totals and metrics - Reference steps 12-15
A43: Build spent = soft actual + hard actual | B43: =SoftActual+HardActual
A44: Financing | B44: =SUM(colPoints)+LandPoints+SUM(colInterest)+SUM(colLandInterest)+SUM(colDrawFee)+SUM(colExtensionFee)
A45: Carry | B45: =SUM(colTax)+SUM(colInsurance)+SUM(colUtilities)+SUM(colStaging)+SUM(colUpkeep)+SUM(colHoa)
...

Sheet stress
A1: Golden deal - stress scenario
A2: Every value below is a formula implementing the Reference cash-flow algorithm (dollars).
A4: Scenario inputs
A5: Sale price | B5: =Inputs!$B$47
A6: Days on market | B6: =Inputs!$C$47
A7: Cost overrun | B7: =Inputs!$D$47
A9: Times (months) - Reference step 1
A10: Build start = P | B10: =PreConMonths
A11: Completion = P + B | B11: =BuildStart+BuildMonths
A12: List = completion - L | B12: =Completion-ListEarlyMonths
A13: Contract = list + DOM / MONTH_DAYS | B13: =ListMonth+DomDays/MonthDays
A14: Sale close = max(contract + closingDays / MONTH_DAYS, completion) | B14: =MAX(Contract+ClosingDays/MonthDays,Completion)
A15: Loan maturity = build start + term | B15: =BuildStart+TermMonths
A16: Periods N = ceil(sale close) | B16: =CEILING(SaleClose,1)
A17: Period rows in this sheet | B17: =COUNT(colK)
A19: Costs and loan - Reference steps 2-8
A20: Soft actual = round(soft x (1 + overrun)) | B20: =ROUND(SoftCost*(1+Overrun),2)
A21: Hard actual = round(hard x (1 + overrun)) | B21: =ROUND(HardCost*(1+Overrun),2)
A22: Sum of draw sines | B22: =SUM(colSine)
A23: Loan commitment = round(LTC x estimate total) | B23: =ROUND(Ltc*EstimateTotal,2)
A24: Equity requirement = estimate total - commitment | B24: =EstimateTotal-Commitment
A25: Construction points = round(points x commitment) | B25: =IF(Commitment>0,ROUND(PointsPct*Commitment,2),0)
A26: Land loan = round(LTV x land price) | B26: =ROUND(LandLtv*LandPrice,2)
A27: Land points = round(points x land loan) | B27: =ROUND(LandPointsPct*LandLoan,2)
A28: Extensions n | B28: =IF(AND(Commitment>0,SaleClose>Maturity),CEILING((SaleClose-Maturity)/ExtensionMonths,1),0)
A29: Extension fee each = round(extension % x commitment) | B29: =ROUND(ExtensionPct*Commitment,2)
A30: Interest capitalized (1 = yes) | B30: =IF(InterestMode="capitalized",1,0)
A32: Sale (at sale close, booked on period N-1) - Reference step 11
A33: Commissions = round(price x (listing + buyer)) | B33: =ROUND(SalePrice*(ListingPct+BuyerPct),2)
A34: Closing = round(price x closing %) | B34: =ROUND(SalePrice*ClosingPct,2)
A35: Concessions | B35: =Concessions
A36: Net = price - commissions - closing - concessions | B36: =SalePrice-Commissions-SaleClosing-SaleConcessions
A37: Loan drawn | B37: =SUM(colLoanDraw)
A38: Capitalized interest | B38: =SUM(colInterestCap)
A39: Loan payoff = drawn + capitalized interest + land loan | B39: =LoanDrawn+CapInterest+LandLoan
A40: Equity return = net - payoff | B40: =NetProceeds-Payoff
A42: Totals and metrics - Reference steps 12-15
A43: Build spent = soft actual + hard actual | B43: =SoftActual+HardActual
A44: Financing | B44: =SUM(colPoints)+LandPoints+SUM(colInterest)+SUM(colLandInterest)+SUM(colDrawFee)+SUM(colExtensionFee)
A45: Carry | B45: =SUM(colTax)+SUM(colInsurance)+SUM(colUtilities)+SUM(colStaging)+SUM(colUpkeep)+SUM(colHoa)
...
